<?xml version="1.0" encoding="utf-8"?>
<!-- This URDF was automatically created by SolidWorks to URDF Exporter! Originally created by Stephen Brawner (brawner@gmail.com) 
     Commit Version: 1.6.0-1-g15f4949  Build Version: 1.6.7594.29634
     For more information, please see http://wiki.ros.org/sw_urdf_exporter -->
<robot
  name="box assembly.SLDASM">
  <link
    name="base_link">
    <inertial>
      <origin
        xyz="-0.0274580289969885 -0.0207105005455901 -0.00905536026965592"
        rpy="0 0 0" />
      <mass
        value="9.70303539967061" />
      <inertia
        ixx="0.0233998461844056"
        ixy="-3.35979080212373E-18"
        ixz="2.05721058189735E-34"
        iyy="0.0779792534667865"
        iyz="1.33862046966629E-18"
        izz="0.0910291952248767" />
    </inertial>
    <visual>
      <origin
        xyz="0 0 0"
        rpy="0 0 0" />
      <geometry>
        <mesh
          filename="package://box assembly.SLDASM/meshes/base_link.STL" />
      </geometry>
      <material
        name="">
        <color
          rgba="0.898039215686275 0.917647058823529 0.929411764705882 1" />
      </material>
    </visual>
    <collision>
      <origin
        xyz="0 0 0"
        rpy="0 0 0" />
      <geometry>
        <mesh
          filename="package://box assembly.SLDASM/meshes/base_link.STL" />
      </geometry>
    </collision>
  </link>
  <link
    name="link_one">
    <inertial>
      <origin
        xyz="3.46944695195361E-18 0.0348337852081766 0"
        rpy="0 0 0" />
      <mass
        value="0.496146018366026" />
      <inertia
        ixx="0.000472189192152281"
        ixy="-6.07421701937923E-20"
        ixz="9.06748770035729E-19"
        iyy="0.000604174710033628"
        iyz="-2.16911456103217E-20"
        izz="0.000538862076956333" />
    </inertial>
    <visual>
      <origin
        xyz="0 0 0"
        rpy="0 0 0" />
      <geometry>
        <mesh
          filename="package://box assembly.SLDASM/meshes/link_one.STL" />
      </geometry>
      <material
        name="">
        <color
          rgba="0.792156862745098 0.819607843137255 0.933333333333333 1" />
      </material>
    </visual>
    <collision>
      <origin
        xyz="0 0 0"
        rpy="0 0 0" />
      <geometry>
        <mesh
          filename="package://box assembly.SLDASM/meshes/link_one.STL" />
      </geometry>
    </collision>
  </link>
  <joint
    name="joint_one"
    type="continuous">
    <origin
      xyz="-0.102589157553393 -0.0207105005455901 0.0309446397303441"
      rpy="1.5707963267949 0 1.58235907148083" />
    <parent
      link="base_link" />
    <child
      link="link_one" />
    <axis
      xyz="0 1 0" />
  </joint>
  <link
    name="link_two">
    <inertial>
      <origin
        xyz="0.197504472468739 2.46989928509578E-14 -2.24820162486594E-15"
        rpy="0 0 0" />
      <mass
        value="2.10728761101962" />
      <inertia
        ixx="0.00352146866814831"
        ixy="-2.29945220037251E-15"
        ixz="2.49341637931175E-16"
        iyy="0.0218829260185023"
        iyz="2.83789918648081E-17"
        izz="0.0243396535915128" />
    </inertial>
    <visual>
      <origin
        xyz="0 0 0"
        rpy="0 0 0" />
      <geometry>
        <mesh
          filename="package://box assembly.SLDASM/meshes/link_two.STL" />
      </geometry>
      <material
        name="">
        <color
          rgba="0.792156862745098 0.819607843137255 0.933333333333333 1" />
      </material>
    </visual>
    <collision>
      <origin
        xyz="0 0 0"
        rpy="0 0 0" />
      <geometry>
        <mesh
          filename="package://box assembly.SLDASM/meshes/link_two.STL" />
      </geometry>
    </collision>
  </link>
  <joint
    name="joint_two"
    type="continuous">
    <origin
      xyz="0 0.05 0"
      rpy="3.14159265358979 -0.218531438814536 1.57079632679502" />
    <parent
      link="link_one" />
    <child
      link="link_two" />
    <axis
      xyz="0 1 0" />
  </joint>
  <link
    name="link_three">
    <inertial>
      <origin
        xyz="0.0966050100448868 0.0325982245755421 3.36536354339501E-16"
        rpy="0 0 0" />
      <mass
        value="1.13547562843725" />
      <inertia
        ixx="0.00124504244325037"
        ixy="-0.00136038341867333"
        ixz="1.70931248755918E-18"
        iyy="0.025570320079562"
        iyz="-5.28548559086683E-19"
        izz="0.0257880925814325" />
    </inertial>
    <visual>
      <origin
        xyz="0 0 0"
        rpy="0 0 0" />
      <geometry>
        <mesh
          filename="package://box assembly.SLDASM/meshes/link_three.STL" />
      </geometry>
      <material
        name="">
        <color
          rgba="0.792156862745098 0.819607843137255 0.933333333333333 1" />
      </material>
    </visual>
    <collision>
      <origin
        xyz="0 0 0"
        rpy="0 0 0" />
      <geometry>
        <mesh
          filename="package://box assembly.SLDASM/meshes/link_three.STL" />
      </geometry>
    </collision>
  </link>
  <joint
    name="joint_three"
    type="continuous">
    <origin
      xyz="0.391000000000002 0 0"
      rpy="-1.57079632679497 -1.41730518898606 0" />
    <parent
      link="link_two" />
    <child
      link="link_three" />
    <axis
      xyz="0 0 1" />
  </joint>
  <link
    name="link_four">
    <inertial>
      <origin
        xyz="-9.71445146547012E-17 0.00989938457592143 -5.55111512312578E-17"
        rpy="0 0 0" />
      <mass
        value="0.034317902754904" />
      <inertia
        ixx="1.54842126880431E-05"
        ixy="-3.48606997354348E-20"
        ixz="3.56812629030874E-19"
        iyy="5.65148521425934E-05"
        iyz="2.30287082534763E-20"
        izz="6.51748950462002E-05" />
    </inertial>
    <visual>
      <origin
        xyz="0 0 0"
        rpy="0 0 0" />
      <geometry>
        <mesh
          filename="package://box assembly.SLDASM/meshes/link_four.STL" />
      </geometry>
      <material
        name="">
        <color
          rgba="0.792156862745098 0.819607843137255 0.933333333333333 1" />
      </material>
    </visual>
    <collision>
      <origin
        xyz="0 0 0"
        rpy="0 0 0" />
      <geometry>
        <mesh
          filename="package://box assembly.SLDASM/meshes/link_four.STL" />
      </geometry>
    </collision>
  </link>
  <joint
    name="joint_four"
    type="continuous">
    <origin
      xyz="0.487991135076232 0.0450000000000007 0"
      rpy="0 -1.42086851891227 -1.5707963267949" />
    <parent
      link="link_three" />
    <child
      link="link_four" />
    <axis
      xyz="0 1 0" />
  </joint>
  <link
    name="link_five">
    <inertial>
      <origin
        xyz="0.000280506454183913 1.11022302462516E-16 -0.00742880546848129"
        rpy="0 0 0" />
      <mass
        value="0.110317203673205" />
      <inertia
        ixx="2.58845788049668E-05"
        ixy="6.14098886759368E-20"
        ixz="-2.29882064744539E-07"
        iyy="9.08688682412563E-05"
        iyz="-1.81582688067641E-20"
        izz="7.95846864822047E-05" />
    </inertial>
    <visual>
      <origin
        xyz="0 0 0"
        rpy="0 0 0" />
      <geometry>
        <mesh
          filename="package://box assembly.SLDASM/meshes/link_five.STL" />
      </geometry>
      <material
        name="">
        <color
          rgba="0.792156862745098 0.819607843137255 0.933333333333333 1" />
      </material>
    </visual>
    <collision>
      <origin
        xyz="0 0 0"
        rpy="0 0 0" />
      <geometry>
        <mesh
          filename="package://box assembly.SLDASM/meshes/link_five.STL" />
      </geometry>
    </collision>
  </link>
  <joint
    name="joint_five"
    type="continuous">
    <origin
      xyz="0 0.0363088649237702 0"
      rpy="1.14381079025874 0 0" />
    <parent
      link="link_four" />
    <child
      link="link_five" />
    <axis
      xyz="1 0 0" />
  </joint>
  <link
    name="end_effector">
    <inertial>
      <origin
        xyz="-0.0299999999999999 0.0250876489030857 -0.0300000000000005"
        rpy="0 0 0" />
      <mass
        value="0.179214601836603" />
      <inertia
        ixx="9.11730102256747E-05"
        ixy="3.64224167319349E-20"
        ixz="-1.27054942088145E-20"
        iyy="0.000107990182522958"
        iyz="-6.73391193067169E-20"
        izz="9.11730102256747E-05" />
    </inertial>
    <visual>
      <origin
        xyz="0 0 0"
        rpy="0 0 0" />
      <geometry>
        <mesh
          filename="package://box assembly.SLDASM/meshes/end_effector.STL" />
      </geometry>
      <material
        name="">
        <color
          rgba="0.792156862745098 0.819607843137255 0.933333333333333 1" />
      </material>
    </visual>
    <collision>
      <origin
        xyz="0 0 0"
        rpy="0 0 0" />
      <geometry>
        <mesh
          filename="package://box assembly.SLDASM/meshes/end_effector.STL" />
      </geometry>
    </collision>
  </link>
  <joint
    name="fixed_end"
    type="fixed">
    <origin
      xyz="-0.0300000000000009 -0.0300000000000019 -0.0300000000000005"
      rpy="-1.57079632679489 0 3.14159265358979" />
    <parent
      link="link_five" />
    <child
      link="end_effector" />
    <axis
      xyz="0 0 0" />
  </joint>
</robot>